<?xml version="1.0" encoding="UTF-8"?>
<testng-results skipped="0" failed="1" ignored="0" total="1" passed="0">
  <reporter-output>
    <line>
      <![CDATA[ASSERT FALLIDO: expected [Búsqueda de Créditoo] but found [Búsqueda de Crédito]]]>
    </line>
  </reporter-output>
  <suite name="Default suite" duration-ms="4549" started-at="2021-08-30T17:58:55Z" finished-at="2021-08-30T17:59:00Z">
    <groups>
    </groups>
    <test name="Default test" duration-ms="4549" started-at="2021-08-30T17:58:55Z" finished-at="2021-08-30T17:59:00Z">
      <class name="scripts.Tests">
        <test-method status="PASS" signature="beforeMethod()[pri:0, instance:scripts.Tests@309e345f]" name="beforeMethod" is-config="true" duration-ms="2994" started-at="2021-08-30T13:58:55Z" finished-at="2021-08-30T13:58:58Z">
          <reporter-output>
          </reporter-output>
        </test-method> <!-- beforeMethod -->
        <test-method status="FAIL" signature="Prueba()[pri:0, instance:scripts.Tests@309e345f]" name="Prueba" duration-ms="1537" started-at="2021-08-30T13:58:58Z" finished-at="2021-08-30T13:59:00Z">
          <exception class="java.lang.AssertionError">
            <message>
              <![CDATA[ASSERT FALLIDO: expected [Búsqueda de Créditoo] but found [Búsqueda de Crédito]]]>
            </message>
            <full-stacktrace>
              <![CDATA[java.lang.AssertionError: ASSERT FALLIDO: expected [Búsqueda de Créditoo] but found [Búsqueda de Crédito]
	at org.testng.Assert.fail(Assert.java:94)
	at utils.Acciones.assertTextosIguales(Acciones.java:185)
	at pages.PLogin.Login(PLogin.java:49)
	at scripts.Tests.Prueba(Tests.java:101)
	at sun.reflect.NativeMethodAccessorImpl.invoke0(Native Method)
	at sun.reflect.NativeMethodAccessorImpl.invoke(NativeMethodAccessorImpl.java:62)
	at sun.reflect.DelegatingMethodAccessorImpl.invoke(DelegatingMethodAccessorImpl.java:43)
	at java.lang.reflect.Method.invoke(Method.java:498)
	at org.testng.internal.MethodInvocationHelper.invokeMethod(MethodInvocationHelper.java:104)
	at org.testng.internal.Invoker.invokeMethod(Invoker.java:645)
	at org.testng.internal.Invoker.invokeTestMethod(Invoker.java:851)
	at org.testng.internal.Invoker.invokeTestMethods(Invoker.java:1177)
	at org.testng.internal.TestMethodWorker.invokeTestMethods(TestMethodWorker.java:129)
	at org.testng.internal.TestMethodWorker.run(TestMethodWorker.java:112)
	at org.testng.TestRunner.privateRun(TestRunner.java:756)
	at org.testng.TestRunner.run(TestRunner.java:610)
	at org.testng.SuiteRunner.runTest(SuiteRunner.java:387)
	at org.testng.SuiteRunner.runSequentially(SuiteRunner.java:382)
	at org.testng.SuiteRunner.privateRun(SuiteRunner.java:340)
	at org.testng.SuiteRunner.run(SuiteRunner.java:289)
	at org.testng.SuiteRunnerWorker.runSuite(SuiteRunnerWorker.java:52)
	at org.testng.SuiteRunnerWorker.run(SuiteRunnerWorker.java:86)
	at org.testng.TestNG.runSuitesSequentially(TestNG.java:1293)
	at org.testng.TestNG.runSuitesLocally(TestNG.java:1218)
	at org.testng.TestNG.runSuites(TestNG.java:1133)
	at org.testng.TestNG.run(TestNG.java:1104)
	at org.testng.remote.AbstractRemoteTestNG.run(AbstractRemoteTestNG.java:115)
	at org.testng.remote.RemoteTestNG.initAndRun(RemoteTestNG.java:251)
	at org.testng.remote.RemoteTestNG.main(RemoteTestNG.java:77)
]]>
            </full-stacktrace>
          </exception> <!-- java.lang.AssertionError -->
          <reporter-output>
            <line>
              <![CDATA[ASSERT FALLIDO: expected [Búsqueda de Créditoo] but found [Búsqueda de Crédito]]]>
            </line>
          </reporter-output>
        </test-method> <!-- Prueba -->
      </class> <!-- scripts.Tests -->
    </test> <!-- Default test -->
  </suite> <!-- Default suite -->
</testng-results>
